Workbook
Name dd_attributes: 'PDP Checklist'!$B$15:$O$44

Sheet Table of Contents
B3: Table of Contents | E3: Always use the latest version of this file
B5: =HYPERLINK(VLOOKUP("Section",'PDP Checklist'!A:O,2,FALSE),"PDP Checklist READ ME") -> PDP Checklist READ ME | C5: Product information required for digital health. Utilize this Checklist during NPI to capture digital product information for hand-off to operational resources. | E5: Please provide any feedback on this Checklist, Training, or Process on our Feedback Form!
B6: =HYPERLINK(VLOOKUP("Section",'PDP Checklist'!A:O,2,FALSE),"PDP Checklist") -> PDP Checklist | D6: #'PDP Checklist READ ME'!C5
B8: Learn More & Support | C8: Descriptions, best practices, and additional information for each required product information data/element of the PDP Checklist
B10: Operational Resources | C10: Operational (systems) information, reminders, dependencies, tips & tricks, etc. for each requirement on the checklist, CorpBase entry, and data def job aid instructions.
B12: Data Definition Job Aid | C12: Standardized table of required attributes for a specified product group and type.

Sheet PDP Checklist READ ME
A1: PDP Checklist READ ME
A2: Always use the latest version.
A3: =HYPERLINK(C3,"Why use the PDP Checklist?") -> Why use the PDP Checklist? | C3: #'PDP Checklist READ ME'!C6
A4: =HYPERLINK(C4,"Best in Class PDP") -> Best in Class PDP | C4: #'PDP Checklist READ ME'!C47
A5: =HYPERLINK(C5,"Example of Completed Checklist") -> Example of Completed Checklist | C5: #'PDP Checklist READ ME'!M47
C6: Why use the PDP Checklist? | F6: UPDATE TO THE DATA DEF JOB AID / PDP CHECKLIST
F7: The data def job aid and PDP Checklists have now been combined into one file (this file). Future updates to the the Data Definition job aid tab will automatically update the attributes/properties dynamic table on the PDP Checklist. This will ensure all PMs are using up to date product data recommendations during NPI and data def review. Please be sure to always use the latest version of this file
C8: WHAT is a 'Digital Checklist'? | D8: The Digital Requirements Checklist is a list of product information data & elements that are required for a 'healthy' digital presence on sigmaaldrich.com; the checklist can also be used to capture data for hand-off to operational resources. The requirements represent product data and elements that appear on a product detail page (PDP), within site search, on a category page, etc.
C10: WHO is involved? | D10: PRODUCT MARKETING is responsible for identifying the product data and content to meet the requirements. Product Marketing is the primary audience and expected user group of the Digital Requirements Checklist, responsible for capturing product information and handing over to operational resources for systems updates. OPERATIONAL RESOURCES (e.g. PM Ops, SBS, etc.) are responsible for ensuring product data and content is entered into systems accurately and completely.
C12: WHEN is the checklist used? | D12: The Digital Requirements Checklist should be referenced throughout New Product Introduction (NPI), from ideation to systems set up, so that critical product information can be collected and/or generated in accordance with digital best practices.
C14: WHERE can I find more support? | D14: The 'Learn More & Best Practices' tab provides a description of each element alongside recommended best practices; additional resources, found on EVA, are also provided. Support can also be provided by Digital Category Management, Product Data team, and the Digital Champions Network.
C16: WHY is this so important? | D16: Capturing accurate, complete product information is critical to a PDP's digital health. Launching an NPI with the required product information outlined on the Digital Requirements Checklist will: • Provide product information a customer needs to identify, select & buy a product of interest • Improve product findability within site search • Impact organic search ranking through SEO • Support post-purchase product use • Meet customer expectations of a consistent & intuitive user experience • Better enable scalable acquisition & marketing activities
C19: Best in Class PDP | F19: Example of Completed Checklist:
C20: https://www.sigmaaldrich.com/product/sigma/hpa002891 | F20: Product Info | H20: CorpBase Product Number | I20: =HYPERLINK(VLOOKUP(H20,'Learn More & Support'!$B:$D,2,0),"learn more") -> learn more | J20: New Product Number, must be same as SAP BISMT. Not always = SKU | M20: HPA002891
H21: CorpBase Brand | I21: =HYPERLINK(VLOOKUP(H21,'Learn More & Support'!$B:$D,2,0),"learn more") -> learn more | J21: CorpBase brand, NOT portfolio brand | M21: SIGMA
H22: CorpBase Substance | I22: =HYPERLINK(VLOOKUP(H22,'Learn More & Support'!$B:$D,2,0),"learn more") -> learn more | J22: If applicable; A CB substance shares attributes & search assortment | M22: n/a
H23: Product Group | I23: =HYPERLINK(VLOOKUP(H23,'Learn More & Support'!$B:$D,2,0),"learn more") -> learn more | J23: antibodies | M23: <-- 1. Select Product Group
H24: Product Type | I24: =HYPERLINK(VLOOKUP(H24,'Learn More & Support'!$B:$D,2,0),"learn more") -> learn more | J24: primary monoclonal | M24: <-- 2. Select Product Type
H25: IF PRODUCT GROUP/TYPE DOES NOT EXIST, STOP. CONTACT DCM TO REVIEW DATA DEFINITIONS.
F27: Names | H27: Primary name | I27: =HYPERLINK(VLOOKUP(H27,'Learn More & Support'!$B:$D,2,0),"learn more") -> learn more | J27: Aligns with name in MDGM | M27: Anti-AKT1 antibody produced in rabbit
H28: Name suffix | I28: =HYPERLINK(VLOOKUP(H28,'Learn More & Support'!$B:$D,2,0),"learn more") -> learn more | J28: Auto-populate: Select Attributes & Order below (or enter free text) | M28: Prestige Antibodies® Powered by Atlas Antibodies, affinity isolated antibody, buffered aqueous glycerol solution
H29: Synonyms | I29: =HYPERLINK(VLOOKUP(H29,'Learn More & Support'!$B:$D,2,0),"learn more") -> learn more | J29: Provide at least 1-2 synonyms | M29: Anti-RAC-PK-α antibody produced in rabbit, Anti-Protein kinase B antibody produced in rabbit, Anti-PKB antibody produced in rabbit, Anti-RAC-α serine/threonine-protein kinase antibody produced in rabbit, Anti-C-AKT antibody produced in rabbit
F31: Properties | G31: Suffix Order | H31: Attributes | I31: Priority | J31: Example Product | K31: Example Data | L31: Facet | M31: Attribute Data/Value:
F32: =HYPERLINK(VLOOKUP(H31,'Learn More & Support'!$B:$D,2,0),"learn more") -> learn more | H32: antibody form | I32: Priority 1 | J32: MAB5608 | K32: ascites fluid | L32: Y | M32: affinity isolated antibody
H33: biological source | I33: Priority 1 | J33: MAB5608 | K33: mouse | L33: Y | M33: rabbit
H34: clone | I34: Priority 1 | J34: MAB5608 | K34: GT1b-2b, monoclonal | L34: Y | M34: polyclonal
F35: for more resources: | H35: concentration | I35: Priority 2 | J35: M2320 | K35: ~2 mg/mL | L35: N
F36: Data Def Job Aid | H36: conjugate | I36: Priority 1 | J36: MABF2815 | K36: unconjugated | L36: Y | M36: unconjugated
F37: Fixed Text Picklist | H37: enhanced validation | I37: Priority 2 | J37: AMAB91124 | K37: orthogonal RNAseq | L37: N | M37: orthogonal RNAseq
H38: form | I38: Priority 1 | J38: GR01 | K38: liquid | L38: Y | M38: buffered aqueous glycerol solution
H39: Gene Information | I39: Priority 1 | J39: MAB1687 | K39: human ... VIM(7431) | L39: Y | M39: human ... AKT1(207)
H40: greener alternative category | I40: Priority 3 | J40: 0 | K40: 0 | L40: 0
H41: greener alternative product characteristics | I41: Priority 3 | J41: 0 | K41: 0 | L41: 0
H42: immunogen sequence | I42: Priority 3 | J42: AMAB91124 | K42: LNLSSIILDVNQDRLTQRAIEASNAYSRILQAVQAAEDAAGQALQQADHTWATVVRQGLVDRAQQLLANSTALEEAMLQEQQRLGLVWAAL | L42: N | M42: ERTFHVETPEEREEWTTAIQTVADGLKKQEEEEMDFRSGSPSDNSGAEEMEVSLAKPKHRVTMNEFEYLKLLGKGTFGKVILVKEKATGRYYAMKILKKEVIVA,seq:16,language:1,id:
H43: isotype | I43: Priority 1 | J43: MAB5608 | K43: IgG2b | L43: Y
H44: manufacturer/tradename | I44: Priority 3 | J44: 0 | K44: 0 | L44: 0
H45: mol wt | I45: Priority 1 | J45: M2320 | K45: apparent mol wt 280 kDa | L45: N
H46: NCBI accession no. | I46: Priority 2 | J46: MAB1687 | K46: NM_003380.2 | L46: N
H47: packaging | I47: Priority 3 | J47: AMAB91124 | K47: antibody small pack of 25 μL | L47: Y | M47: antibody small pack of 25 μL
H48: product line | I48: Priority 2 | J48: AMAB91124 | K48: Prestige Antibodies® Powered by Atlas Antibodies | L48: Y | M48: Prestige Antibodies® Powered by Atlas Antibodies
...

Sheet PDP Checklist
A1: =HYPERLINK(O1,"Example provided on 'READ ME' tab") -> Example provided on 'READ ME' tab | O1: #'PDP Checklist READ ME'!M46
A2: Section | C2: Product Information Element Click to Learn More | D2: Hidden for dynamic attributes table | E2: Hidden for dynamic attributes table | F2: Hidden for dynamic attributes table | G2: Hidden for dynamic attributes table | H2: Hidden for dynamic attributes table | I2: Quick notes | L2: Hidden for dynamic attributes table | M2: Hidden for dynamic attributes table | N2: Hidden for dynamic attributes table | O2: Input (by Product Marketing) | P2: Copy Input (Column L) to compare data if launching similar products ↓
A3: Product Info | C3: =HYPERLINK(VLOOKUP("CorpBase Product Number",'Learn More & Support'!B:D,2,0),"CorpBase Product Number") -> CorpBase Product Number | I3: New Product Number, must be same as SAP BISMT. Not always = SKU | O3: PMC1108
C4: =HYPERLINK(VLOOKUP("CorpBase Brand",'Learn More & Support'!B:D,2,0),"CorpBase Brand") -> CorpBase Brand | I4: CorpBase brand, NOT portfolio brand | O4: SIAL
C5: =HYPERLINK(VLOOKUP("CorpBase Substance",'Learn More & Support'!B:D,2,0),"CorpBase Substance") -> CorpBase Substance | I5: If applicable; A CB substance shares attributes & search assortment
I6: SELECT PRODUCT GROUP/TYPE. If none apply, contact DCM
C7: =HYPERLINK(VLOOKUP("Product Group",'Learn More & Support'!B:D,2,0),"Product Group") -> Product Group | I7: stable isotopes | O7: <-- 1. Select Product Group
C8: =HYPERLINK(VLOOKUP("Product Type",'Learn More & Support'!B:D,2,0),"Product Type") -> Product Type | I8: various | O8: <-- 2. Select Product Type
A10: Names | C10: Primary name | I10: Aligns with name in MDGM | O10: Methanol-d4
C11: Name suffix | I11: Recommended: Input relevant Attributes & select "Suffix Order" below | O11: ≥99.8% D, ISOM8™
C12: Synonyms | I12: Provide at least 1-2 synonyms | O12: methyl-d3- alcohol d, tetradeuteromethanol
A14: Properties | B14: Suffix Order | C14: Attributes | D14: Priority - change to number | E14: Priority | I14: Example Product | J14: Example Data | K14: Facet | O14: Attribute Data/Value:
A15: =HYPERLINK(VLOOKUP(C14,'Learn More & Support'!$B:$D,2,0),"learn more") -> learn more | C15: {=IFERROR( IF($I$7="_discontinued","Select Product Group & Product Type",_xlfn._xlws.FILTER(LOGIC!K:V,LOGIC!H:H=$I$7&IF($I$8=0,"",$I$8))),"Enter valid Product Group AND Product Type")} -> assay | D15: Facet driving attribute | E15: Priority 1 | F15: ProductAttributes | G15: ATTRIBUTE TYPE: Assay | H15: 0 | I15: 151866 | J15: ≥99% (CP) | K15: Y | L15: Purity | M15: 0 | N15: 0 | O15: ≥99% (CP)
B16: 1 | C16: form | D16: Facet driving attribute | E16: Priority 1 | F16: ProductAttributes | G16: ATTRIBUTE TYPE: Physical Form | H16: 0 | I16: 151866 | J16: liquid | K16: Y | L16: Physical Form | M16: 0 | N16: 0 | O16: liquid
A17: additional resources: | C17: grade | D17: Facet driving attribute | E17: Priority 1 | F17: ProductAttributes | G17: ATTRIBUTE TYPE: Special Grade and web special grade | H17: web special grade is facetable; but web special grade does not show on the PDP; special grade is the opposite | I17: 154784 | J17: spectrophotometric grade | K17: Y | L17: grade | M17: 0 | N17: 0 | O17: reagent grade
A18: Fixed Text Picklist | B18: 3 | C18: isotopic purity | D18: Facet driving attribute | E18: Priority 1 | F18: ProductAttributes | G18: ATTRIBUTE TYPE: Isotopic Purity | H18: 0 | I18: 151866 | J18: ≥99.6 atom % D | K18: Y | L18: Isotope | M18: 0 | N18: 0 | O18: ≥99.8 atom % D
C19: mass shift | D19: Facet driving attribute | E19: Priority 1 | F19: ProductAttributes | G19: ATTRIBUTE TYPE: Mass Shift | H19: 0 | I19: 151866 | J19: M+12 | K19: Y | L19: mass shift | M19: 0 | N19: 0 | O19: M+4
C20: technique(s) | D20: Facet driving attribute | E20: Priority 1 | F20: ProductAttributes | G20: ATTRIBUTE TYPE: Titertest | H20: use the drop down in "METHOD" | I20: 151866 | J20: NMR: suitable | K20: Y | L20: Technique | M20: method | N20: method
C21: bp | D21: High priority attribute | E21: Priority 2 | F21: ProductAttributes | G21: ATTRIBUTE TYPE: Boiling Point | H21: 0 | I21: 151866 | J21: 80.7 °C (lit.) | K21: Y | L21: boiling point | M21: 0 | N21: 0 | O21: 65.4 °C (lit)
C22: concentration | D22: High priority attribute | E22: Priority 2 | F22: ProductAttributes | G22: ATTRIBUTE TYPE: Concentration | H22: 0 | I22: 176680 | J22: 50 wt. % in D2O | K22: N | L22: 0 | M22: 0 | N22: 0
C23: density | D23: High priority attribute | E23: Priority 2 | F23: ProductAttributes | G23: ATTRIBUTE TYPE: Density | H23: 0 | I23: 151866 | J23: 0.893 g/mL at 25 °C (lit.) | K23: N | L23: 0 | M23: 0 | N23: 0 | O23: 0.888 g/mL at 25 °C (lit.)
C24: impurities | D24: High priority attribute | E24: Priority 2 | F24: ProductAttributes | G24: ATTRIBUTE TYPE: Impurities | H24: 0 | I24: 151793 | J24: ≤0.0500% water | K24: N | L24: 0 | M24: 0 | N24: 0 | O24: <0.5% water
C25: InChI | D25: High priority attribute | E25: Priority 2 | F25: Aliases | G25: drop down type: InChl | H25: must be on the substance level | I25: 151866 | J25: 1S/C6H12/c1-2-4-6-5-3-1/h1-6H2/i1D2,2D2,3D2,4D2,5D2,6D2 | K25: N | L25: 0 | M25: 0 | N25: 0 | O25: 1S/CH4O/c1-2/h2H,1H3/i1D3,2D
C26: InChI key | D26: High priority attribute | E26: Priority 2 | F26: Aliases | G26: drop down type: InChl key | H26: must be on the substance level | I26: 151866 | J26: XDTMQSROBMDMFD-LBTWDOQPSA-N | K26: N | L26: 0 | M26: 0 | N26: 0 | O26: OKKJLVBELUTLKV-MZCSYVLQSA-N
C27: mp | D27: High priority attribute | E27: Priority 2 | F27: ProductAttributes | G27: ATTRIBUTE TYPE: Melting Point | H27: 0 | I27: 151866 | J27: 6.5 °C (lit.) | K27: Y | L27: mp | M27: 0 | N27: 0
C28: packaging | D28: High priority attribute | E28: Priority 2 | F28: ProductAttributes | G28: ATTRIBUTE TYPE: Packaging quantity | H28: facet only on pack_id (was NEVER used on the red site - utility is dubious) | I28: 151793 | J28: glass bottle of 25 g, 50 g | K28: Y | L28: packaging | M28: pack_id | N28: pack_id | O28: glass bottle of 1g, 5g
C29: refractive index | D29: High priority attribute | E29: Priority 2 | F29: ProductAttributes | G29: ATTRIBUTE TYPE: Refractive Index | H29: 0 | I29: 151866 | J29: n20/D 1.421 (lit.) | K29: N | L29: 0 | M29: 0 | N29: 0 | O29: n20/D 1.326 (lit.)
C30: SMILES string | D30: High priority attribute | E30: Priority 2 | F30: Aliases | G30: drop down type: SMILES | H30: must be on the substance level; 30 characters or less; if more than 30 characters, raise a JIRA for CorpBase Helpdesk | I30: 151866 | J30: [2H]C1([2H])C([2H])([2H])C([2H])([2H])C([2H])([2H])C([2H])([2H])C1([2H])[2H] | K30: N | L30: 0 | M30: 0 | N30: 0 | O30: [2H]OC([2H])([2H])[2H]
C31: storage temp. | D31: High priority attribute | E31: Priority 2 | F31: ProductAttributes | G31: ATTRIBUTE TYPE: Storage Temp | H31: 0 | I31: 1.03643 | J31: 2-30°C | K31: N | L31: 0 | M31: 0 | N31: 0
C32: autoignition temp. | D32: Low priority attribute | E32: Priority 3 | F32: ProductAttributes | G32: ATTRIBUTE TYPE: Autoignition temp | H32: must be on the substance level | I32: 1.03643 | J32: 573 °F | K32: N | L32: 0 | M32: 0 | N32: 0
C33: contains | D33: Low priority attribute | E33: Priority 3 | F33: ProductAttributes | G33: ATTRIBUTE TYPE: Additive | H33: 0 | I33: 176036 | J33: copper as stabilizer | K33: N | L33: 0 | M33: 0 | N33: 0
C34: expl. lim. | D34: Low priority attribute | E34: Priority 3 | F34: ProductAttributes | G34: ATTRIBUTE TYPE: Explosion limit | H34: 0 | I34: 151866 | J34: 0.34-6.3 % (lit.) | K34: N | L34: 0 | M34: 0 | N34: 0
C35: vapor density | D35: Low priority attribute | E35: Priority 3 | F35: ProductAttributes | G35: ATTRIBUTE TYPE: Vapor density vs air | H35: 0 | I35: 151793 | J35: 2 (vs air) | K35: N | L35: 0 | M35: 0 | N35: 0
C36: vapor pressure | D36: Low priority attribute | E36: Priority 3 | F36: ProductAttributes | G36: ATTRIBUTE TYPE: Vapor pressure | H36: 0 | I36: 151793 | J36: 3.67 psi ( 20 °C) | K36: N | L36: 0 | M36: 0 | N36: 0
C38: evapn. residue
B39: 2 | C39: product line | O39: ISOM8™
C40: product line
C41: product type | O41: stable isotopes
C44: If you need additional custom attributes not on this list, please insert new rows above this line
A46: Trademarks | C46: Trademarks | I46: If applicable; Check Trademark table to see if value already exists | O46: [TM="ISOM8"]
...

Sheet Learn More & Support
A1: Section | B1: Required element / *required if applicable | C1: Hyperlink Formula (hide) | D1: Description/Definition | E1: Best Practice | F1: More Information | G1: Who can I reach out to for Support?
A2: Product Structure | B2: CorpBase Product Number | C2: #'Learn More & Support'!B2 | D2: The Corpbase product number appears in the header of the product detail page (PDP) as well as in the page URL. This number is not the full SAP material (SKU) number (e.g. XXXX-25MG), but rather is the 'base' product number, which is captured in SAP as the 'old material number' (BISMT). | E2: CorpBase product number should match the SAP BISMT in PRD, PRE, and PRP; Ensure that the BISMT/brand combination is unique and available in Corpbase | F2: Product Numbers (EVA) | G2: DCM (Consultation)
A3: Product Structure | B3: CorpBase Brand | C3: #'Learn More & Support'!B3 | D3: The CorpBase brand is not the Portfolio Brand; rather, it is a value that aligns with SAP master data. The CorpBase brand appears in the PDP URL. | E3: CorpBase brand should match SAP PRD/PRE Division (SPART) and PRP (Brand_ID); Ensure that the BISMT/brand combination is unique and available in Corpbase | F3: CorpBase and Portfolio Brands (EVA) | G3: DCM (Consultation)
A4: Product Structure | B4: CorpBase Substance | C4: #'Learn More & Support'!B4 | D4: To group similar products under the same primary name. | E4: Use a substance when all products share intrinsic properties, like a primary name or a unique identifier (e.g. CAS number), or when products should be "rolled up" in site search results. | F4: Substance & Product Level (EVA) | G4: DCM (Consultation)
A5: Product Structure | B5: Product Group | C5: #'Learn More & Support'!B5 | D5: Select a Product Group from the Data Definition Job Aid | E5: In the job aid, 1) filter results for the product group and product type of the NPI, 2) select the Properties (attributes) listed as required, 3) paste the Properties into column B of this checklist, then 4) enter product-specific values in Input column | F5: Data Definition (EVA) | G5: DCM (Consultation)
A6: Product Structure | B6: Product Type | C6: #'Learn More & Support'!B6 | D6: The Product Type attribute captures data describing "what it is" for a product and is associated with the product categorization/data definition group. This data is displayed in the 'Product Category' facet (filter) on site search results and on category pages, allowing a customer to refine a set of search results by the type of product they are interested in. | E6: A product type value should describe "what it is", without being so specific or narrow that other products are excluded. Examples: syringe filter, antibody, culture media, solvent, etc. Reference the existing list of product type values when identifying the product type; if a value does not exist, consult Digital Category Management for assistance. | F6: Data Definition (EVA) | G6: DCM (Consultation)
A7: Names | B7: Primary name | C7: #'Learn More & Support'!B7 | D7: A product's primary name appears as the H1 on the product detail page, as the primary designator on site search results and on category pages, and is printed on labels generated from SAP. This name should align with the product name in MDGM. | E7: The primary name should be created with consideration of customer language and search behavior. If a product is added to an existing substance, it will inherit a name automatically. | F7: Product Name and Suffix (EVA) | G7: SBS review (quality check)
A8: Names | B8: Name suffix | C8: #'Learn More & Support'!B8 | D8: A product name suffix is a sub-heading (H2) of the primary product name. A relevant name suffix is an important SEO element, contributes to findability in site search (displays as 'Description' in main site search and is concatenated with the primary name in category page product tables) and allows customers to differentiate between products with the same primary name. | E8: To maintain data continuity, a name suffix should be "built" from attribute data designated in the product data definition (see 'Attributes' section below). Note that the name suffix will print on labels for products manufactured/packaged out of SAP. For custom name suffixes, enter free text (which will be loaded as ID_Clarifier) | F8: Product Name and Suffix (EVA) | G8: SBS review (quality check)
A9: Names | B9: Synonyms | C9: #'Learn More & Support'!B9 | D9: Synonyms are additional names, beyond the primary product name, that the product may be known as. Synonyms are an important SEO element and impact the relevancy of site search results. | E9: A product should have a minimum of 1-2 synonyms that represent what a customer would call the product, not parsed data (e.g. a synonym for Anti-NFE2L2 antibody should be 'Anti-NRF2', not 'NRF2'). Synonyms should represent customer language - what customers call the product; synonyms can be identified from search data, VOC, literature, vendor-provided information, etc. | F9: Product Name and Suffix (EVA) | G9: SBS assistance
A10: Names | B10: Trademarks | C10: #'Learn More & Support'!B10 | D10: Trademarks may appear in product data, including a product's primary name, name suffix, description, etc.; trademarks must be esablished in CorpBase in order to be used in product data. | F10: Trademarks (EVA) | G10: DCM (Consultation)
A11: Aliases | B11: UNSPSC code | C11: #'Learn More & Support'!B11 | D11: United Nations Standard Products and Services Code (UNSPSC) is a 4-5 level taxonomy of products and services for use in eCommerce. This categorization code is critical for B2B customers; products missing these data may be removed from B2B catalogs or downgraded in B2B search results | E11: Assign a code that is as specific as possible (in the lower levels of the taxonomy). https://www.ungm.org/Public/UNSPSC https://www.unspsc.org/library | F11: Aliases (EVA) | G11: SBS assistance
A12: Imagery | B12: Product Image | C12: #'Learn More & Support'!B12 | D12: Relevant product imagery is important product information that helps a customer to identify & select a product of interest, set expectations for what will be received upon order, and for post-purchase product use. The image displays on the PDP; if a product image is not provided, the space is filled with a generic vibrant M. | E12: Imagery best practices, including imagery standards, what makes a good image, image specifications, etc. are described in depth on EVA. A PDP may contain multiple images; display order (sequence) must be defined if multiple images are submitted for a given product. | F12: Images (EVA) | G12: SBS assistance
A13: Imagery | B13: Image caption | C13: #'Learn More & Support'!B13 | D13: Captions are text descriptions of images. Captions provide more information for a product image and are important for accessibility. | E13: Image caption should be relevant, descriptive, and provide additional supporting information. If the same image is being used for multiple products, ensure the caption is applicable to all products. | F13: Images (EVA) | G13: SBS review (quality check)
A14: Imagery | B14: Image alt text | C14: #'Learn More & Support'!B14 | D14: Alt text (alternative text) is a text replacement for an image; used to explain what the image is and what the image is trying to convey to the user. It is important for accessibility, as it displays in place of an image on a webpage if the image fails to load on a user's screen. It is also an important SEO element. | E14: Image alt text should be descriptive and specific, containing details that provide a customer context to the image's topic and help the customer to understand what the image is and why is it relevant to the webpage. Alt text should be less than 125 characters. | F14: Images (EVA)
A15: Imagery | B15: Chemical structure | C15: #'Learn More & Support'!B15 | E15: If applicable. Provide the structure (ChemDraw) to structures@merckgroup.com during NPI | G15: PM Only
A16: Packaging | B16: Pack size (displayed in P&A) | C16: #'Learn More & Support'!B16 | D16: Pack size information displays in the Pricing & Availability clip; gives a quick view of the quantity of product for a given SKU size. | E16: Pack size should represent the total quantity of the material, not the full packaging specs (e.g. "25uL", not "25uL in an amber vial") | F16: Pack size data (EVA) | G16: PM Only
A17: Properties | B17: Attributes | C17: #'Learn More & Support'!B17 | D17: Attributes are characteristics of a product that are captured as structured data in CorpBase and displayed on PDPs as "Properties". Attributes captured for a new product should represent the information that a customer needs to identify, select, order, or use a product, and should consistently be captured across a product group (product category or product type). The set of required attributes for a product group is known as 'data definition'. Attribute data, structured precisely in Corpbase, also drives facets that display on site search results and category pages. This is another reason why complete, standardized attribute data is critical. | E17: Reference the 'NPI Data Definition Process' tab for a full workflow and RACI. Reference the 'Data Definition Job Aid' for required attributes by product group. A new product should first be categorized (identify the product group/type of the product) before the required attributes can be identified. Once categorized, use the Merchandising Scorecard and the Data Definition Job Aid, which document existing data definitions, to identify the web product data that is needed. For each required attribute, provide accurate, customer-facing data, referencing the existing list of attribute values ('picklist values') to ensure that data structure is maintained. If a product group, data definition, or picklist value does not exist, consult Digital Category Management for assistance. | F17: Data Definition (Confluence) | G17: DCM/SBS support (data mining, gap filling, etc)
A18: Descriptions | B18: Descriptions | C18: #'Learn More & Support'!B18 | D18: Description text appears in the "Descriptions" section of the PDP and provides additional product information to customers for use in product selection and post-purchase use. Descriptions are also important SEO elements. There are many different description types, which appear as sub-headings on the PDP; all descriptions are free-text fields. | F18: Descriptions (EVA) | G18: SBS assistance (data mining/proposal with PM approval)
A19: Documentation | B19: Product documents | C19: #'Learn More & Support'!B19 | D19: Product technical and marketing documents provide supporting product information that can assist a customer in product selection and use. Technical documents include user guides, product information sheets, data sheets, and technical bulletins, etc. Marketing documents include flyers, brochures, gated content, etc. Technical and marketing documents are maintained in the digital asset management (DAM) system; this excludes safety and quality documents (e.g. SDS, CoA, CoO). | F19: Documentation Overview (EVA) | G19: PM Only
A20: Peer Reviewed Papers | B20: Citations | C20: #'Learn More & Support'!B20 | D20: Citing peer reviewed publications that use a product can provide a social proof point to customers as well as providing additional content about the product's use. | E20: Citations should be relevant to the product and provided as PMID numbers. | F20: Citations and peer reviewed papers (EVA) | G20: SBS assistance
A21: Related Products | B21: Related products | C21: #'Learn More & Support'!B21 | D21: A curated list of related products can provide customers insight into additional relevant products, such as products that are "required but not included", accessories or consumables, replacements or recommended products, etc. | E21: Indicate the relationship of products (e.g. "recommended with", "for use with", etc.) and the directionality of the relationship (e.g. product X is related to product Y unidirectionally, or product X and product Y are related to each other bidirectionally). There is a Maximum number of related products allowed. | F21: Related Products (EVA) | G21: PM Only (SBS can review post launch)
A22: Digital Optimization | B22: Keywords | C22: #'Learn More & Support'!B22 | D22: Keywords contribute to relevancy of site search results, but they do not publish on the PDP (are not customer-facing). | E22: Keywords should be relevant to the product and represent words or terms that a customer might search when looking for the product. Do not include keywords that would result in a customer seeing irrelevant or erroneous products in a search. | G22: SBS review (quality check)
A23: Digital Optimization | B23: Meta title | C23: #'Learn More & Support'!B23 | D23: Meta title (title tag) is text that displays in external search engine (e.g. Google) results and browser tabs for a webpage. A custom meta title offers an opportunity to provide more relevant information/positioning to customers and is an important SEO element. | E23: Existing PDP data (e.g. primary name, CAS #, etc.) is used when custom meta title has not been captured. When crafting a custom meta title, include keywords identified from search data to reflect the words and behaviors of customers. Custom meta titles should be 55-65 characters long and include the core keyword​. Must be unique (do not duplicate on other pages) | G23: SBS review (quality check)
A24: Digital Optimization | B24: Meta description | C24: #'Learn More & Support'!B24 | D24: Meta description is the brief summary text that displays in external search engine (e.g. Google) results for a webpage. The text should give a customer an idea of the content that is on the page. Meta description is an important SEO element. | E24: Existing PDP data is used when custom meta description has not been captured. When crafting a custom meta description, it should be <200 characters long and use relevant keywords. Ensure that it aligns with on-page content. Summarize and accurately describe the content the user will find on the page and provide motivation to read it (a CTA – Call To Action)​. Must be unique (do not duplicate on other pages) | G24: SBS review (quality check)
A25: Digital Optimization | B25: Product Category page | C25: #'Learn More & Support'!B25 | D25: Products may be included on Product Category Pages, which present a key group of related products and supporting content to allow customers to compare, select & order products of interest. | E25: Product Category Pages are not a comprehensive product taxonomy, so not all products will appear on a category page. Products should be added to existing category pages only when relevant; discussion with all impacted business stakeholders should precede product addition. New category page requests must go through Marcom. | F25: Product Category (EVA) | G25: SBS review (quality check)
A26: Digital Optimization | B26: Call to Action | C26: #'Learn More & Support'!B26 | D26: Call to Actions (CTAs) are buttons on the P&A clip which direct the customer to a sigmaaldrich.com lead generation form. The CTA information is stored in CorpBase. | E26: A given PDP can have one “Request a Bulk Order” CTA, and one additional non-Bulk CTA for a maximum of two CTAs. If you do not want a “Request a Bulk Order” CTA, you can have a maximum of one CTA. See EVA page for full list of options, and instructions on how to fill out the template and work with DCM to load. | F26: Call to Action (CTAs) Button (EVA) | G26: PM Only
A27: Digital Optimization | B27: Legacy Legal Entity | C27: #'Learn More & Support'!B27 | D27: This field should be reviewed depending on if you want a product to be available on the sigmaaldrich.com AND/OR sigmaaldrich.cn (China only) & other consolidated websites. For example, if the value is left blank, it is going to default to "Sigma-Aldrich" (showing in the SIAL.com and not .cn (China only). For NPI, make sure it’s Sigma-Aldrich or Merck/Sigma-Aldrich; unless you are directed otherwise for Blue China BoR only, then it’s Merck. Unless there is a specific reason not to sell in China, our suggestion is to use Merck/Sigma-Aldrich. If there are any compliance or sales blocks those will be put in place to prevent these products from being sold on sigmaaldrich.cn. | E27: Please use Merck/Sigma-Aldrich unless directly otherwise. | G27: DCM

Sheet Operational Resources
A1: Operations READ ME | B1: Header Locations
A2: Always use the latest version. | D2: Why use the Data Def Job Aid? | G2: How to use data from PDP Checklist | N2: How to do CorpBase pre-check? | S2: Product data on product labels | W2: YYD_LSIND must match CorpBase product number; YYD_LSWEB must match CorpBase BRAND | AF2: CB Synonym Web Display (and Meta Description JIRA requests) | AJ2: Data Def Workflow | BF2: Call to Action Button Options | BH2: Helpful Links
A3: =HYPERLINK(B3,"Why use the Data Def Job Aid") -> Why use the Data Def Job Aid | B3: #'Operational Resources'!D2 | D3: WHAT is the Data Definition job aid? | E3: The Data Definition job aid outlines the required attribute data (data definition schema) for different product groups. | G3: Section | H3: Product Information Element | I3: More Info & Best Practices | J3: Quick Notes for Operations | K3: How to Implement (Responsible/Accountable: NPI Ops, PM Ops, SBS, etc.) | L3: Watch-outs & Best practices | N3: Method 1: PIM client | O3: https://pim.milliporesigma.io/ | S3: Labels. CorpBase feeds some data to labels such as name, name suffix, CAS number, linear chemical formula, hill notation, Enzyme Commission number, | W3: CorpBase BRAND_ID | X3: CorpBase BRAND_TEXT | Y3: CorpBase BRAND_SHORT | Z3: CorpBase BRAND_DISPLAY | AA3: Notes | AB3: PRD Division (SPART) | AC3: PRE Division (SPART) | AD3: PRP Brand_ID | BF3: Request a Bulk Order | BH3: Product Data EVA Room
A4: =HYPERLINK(B4,"How to use data from PDP Checklist") -> How to use data from PDP Checklist | B4: #'Operational Resources'!G2 | G4: Product Info | H4: =HYPERLINK(VLOOKUP("CorpBase Product Number",'Learn More & Support'!B:D,2,0),"CorpBase Product Number") -> CorpBase Product Number | I4: =HYPERLINK(VLOOKUP(H4,'Learn More & Support'!B:D,2,0),"learn more") -> learn more | J4: SAP BISMT must match CorpBase Product Number; 1 BISMT can have many SKUs on the same PDP page | K4: Batchloader / CorpBase Client | L4: Product must be created in SAP (can be done in parallel). CorpBase product number (and SAP BISMT) should NOT be SKU-specific. Confirm with PM if they enter a SKU as a Product Number, instead of creating one Product Number, with multiple SKUs that share data. | O4: Enter the CorpBase product number (a.k.a. old material number, BISMT) into the PIM | S4: Color Index Number, chemical name synonyms, storage temperature, molecular weight, molecular weight (Daltons) melting point, boiling point, density, | W4: 20 | X4: SIAL | Y4: 1 | Z4: Sigma-Aldrich | AB4: 12, 14 | AC4: 12, 14 | AD4: SA | BF4: =$BF$3&" & "&BF7 -> Request a Bulk Order & Request more information | BH4: Digital Category Management EVA room
A5: =HYPERLINK(B5,"Pre-Check") -> Pre-Check | B5: #'Operational Resources'!N2 | D5: WHO is involved? | E5: PRODUCT MANAGERS can use the job aid to identify/provide the attributes required (columns A-E) during NPI or product data enhancement/clean-up. | O5: If nothing returns, then the product number is available to use. | S5: refractive index, vapor pressure | W5: 22 | X5: VETEC | Y5: V | Z5: Vetec | AB5: V4, V8 | AC5: V4, V8 | AD5: VT | BF5: =$BF$3&" & "&BF8 -> Request a Bulk Order & Request a Sample | BH5: Data Definition Job Aid in Confluence
A6: =HYPERLINK(B6,"Product data on product labels") -> Product data on product labels | B6: #'Operational Resources'!S2 | E6: OPERATIONAL RESOURCES can use the job aid (columns F-H) to understand how to enter data in the correct Corpbase location. | W6: 21 | X6: SAJ | Y6: J | Z6: SAJ | AB6: J8 | AC6: J8 | BF6: =$BF$3&" & "&BF9 -> Request a Bulk Order & Request a Demo | BH6: CorpBase Training Videos
A7: =HYPERLINK(B7,"Brand Match") -> Brand Match | B7: #'Operational Resources'!W2 | S7: This data feeds into an SAP table called ZEHS_MKT_ATTRIB every day through a cron job at 2 AM CST. Products that are marked “Not Ready” will not have | W7: 50 | X7: USP | Y7: X | Z7: USP | AB7: X2 | AC7: X2 | AD7: US | BF7: Request more information | BH7: DCM scorecard
A8: =HYPERLINK(B8,"CB Synonym Web Display") -> CB Synonym Web Display | B8: #'Operational Resources'!AF2 | D8: WHERE can I find what I'm looking for? | E8: Column A-->E: Data Definition Schemas established by the DCM team | H8: =HYPERLINK(VLOOKUP("CorpBase Brand",'Learn More & Support'!B:D,2,0),"CorpBase Brand") -> CorpBase Brand | I8: =HYPERLINK(VLOOKUP(H8,'Learn More & Support'!$B:$D,2,0),"learn more") -> learn more | J8: SAP Brand must match CorpBase Brand: PRD/PRE Division (SPART); PRP Brand (BRAND_ID) | K8: Batchloader / CorpBase Client | L8: Product must be created in SAP (can be done in parallel) | S8: data flow into this table and if there is a brand mismatch between this table and CorpBase, updates will not happen either. | W8: 23 | X8: ROCHE | Y8: K | Z8: Roche | AB8: K5 | AC8: K5 | AD8: RO | BF8: Request a Sample
A9: =HYPERLINK(B9,"Data Def Workflow") -> Data Def Workflow | B9: #'Operational Resources'!AJ2 | E9: Column F-->H: How to enter the product data using the CorpBase batchloader | H9: CorpBase Substance | I9: =HYPERLINK(VLOOKUP(H9,'Learn More & Support'!$B:$D,2,0),"learn more") -> learn more | J9: To group similar products in a substance, they must share the same primary name; new products can be assigned into new or existing substances | K9: Batchloader / CorpBase Client | N9: Method 2: CorpBase | O9: Open the batchloader: https://go.sial.com/Citrix/1912CU1PRODWeb/ | W9: 24 | X9: PM | Y9: P | Z9: Performance Materials | AB9: A2, A4 | AC9: A2, A4 | BF9: Request a Demo | BH9: Batchflow
A10: =HYPERLINK(B10,"Call to Action Button Options") -> Call to Action Button Options | B10: #'Operational Resources'!BF2 | E10: Column I-->J: Example product number and data | H10: Product Group | I10: =HYPERLINK(VLOOKUP(H10,'Learn More & Support'!$B:$D,2,0),"learn more") -> learn more | J10: ='PDP Checklist'!I7 -> stable isotopes | K10: Batchloader / CorpBase Client | L10: During batchloader request to Product Data, indicate selected Product Group | N10: batchloader (Report) | O10: Download the latest version | S10: The product data team can assist with changing data that touches the label but if it outside of that it is not our responsibility. | W10: 9 | X10: Obsolete | Y10: 9 | Z10: Genosys | AA10: Not available in BatchLoader | BH10: NPDI
A11: =HYPERLINK(B11,"Helpful Links") -> Helpful Links | B11: #'Operational Resources'!BH2 | E11: Coumn K-->N: facet related data fields | H11: Product Type | I11: =HYPERLINK(VLOOKUP(H11,'Learn More & Support'!$B:$D,2,0),"learn more") -> learn more | J11: ='PDP Checklist'!I8 -> various | K11: Batchloader / CorpBase Client | L11: During batchloader request to Product Data, indicate selected Product Type | O11: Open the batchloader in Citrix; go to the CorpBase tab; Drop down and select Report | S11: We cannot trouble shoot the SAP tables or templates. | W11: 60 | X11: SIGALD | Y11: Q | Z11: Sigma-Aldrich | AB11: Q4, Q8 | AC11: Q4, Q8 | AD11: SG | BH11: BPM
G12: IF PRODUCT GROUP/TYPE DOES NOT EXIST, STOP. CONTACT DCM TO REVIEW DATA DEFINITIONS. | L12: Confirm PM has used Data Definition job aid and/or worked with Digital Category Management or Product Data | O12: Enter CorpBase product number and brand; Select Primary Name; click Get Report | W12: 70 | X12: HONEYWELL | Y12: H | Z12: Honeywell | AA12: Not available in BatchLoader | AB12: H9 | AC12: H9 | AD12: HW | BH12: Static Content/Blue PDP STEP/Page Edits
D13: WHEN is the job aid used? | E13: During NPI and product data enhancement (clean-up), to identify the required attributes and to ensure data is correctly added to systems. | O13: If nothing shows up under Primary Name, then the product number and brand combo can be used. | S13: The following table was provided by SAP IT (Pradeep) for all fields that can possibly be included on a label. | W13: 80 | X13: BANDJ | Y13: B | Z13: Burdick & Jackson | AA13: Not available in BatchLoader
O14: This function can be done in batch for a list of CorpBase product numbers. | S14: Assay | T14: Enzyme Commision number | U14: Name Suffix | W14: 81 | X14: AVANTI | Y14: T | Z14: Avanti | AB14: T2 | AC14: T2 | AD14: AV | BH14: How to request a new Trademark addition to CorpBase?
D15: WHY is this so important? | E15: The job aid will help to ensure that products appear on the web with a complete & standardized set of product data, | G15: Names | H15: Primary name | I15: =HYPERLINK(VLOOKUP(H15,'Learn More & Support'!$B:$D,2,0),"learn more") -> learn more | J15: CorpBase primary name should match ERP and MDGM product name | K15: Batchloader / CorpBase Client | L15: Primary Name Flag should be marked for the chosen name | S15: Boiling point | T15: Hill notation of chemical formula | U15: Primary Name | W15: 1 | X15: SIGMA | Y15: S | Z15: Sigma | AB15: S2, S4, S8 | AC15: S2, S4, S8 | AD15: SI | BH15: CorpBase HelpDesk and CorpBase Graphics
E16: which will improve product findability (surfacing products in search, enabling facets), present relevant data on a PDP, drive SEO, etc. | H16: Name suffix | I16: =HYPERLINK(VLOOKUP(H16,'Learn More & Support'!$B:$D,2,0),"learn more") -> learn more | J16: Emphasize use of existing Attributes & Order (see below) in CB over free text/ID clarifier | K16: Batchloader / CorpBase Client | L16: Emphasize that it is not best practice to use ID clarifier for name suffix | S16: CAS number | T16: Linear chemical formula | U16: Product storage temperature | W16: 2 | X16: ALDRICH | Y16: A | Z16: Aldrich | AB16: A2, A4 | AC16: A2, A4 | AD16: AL | BH16: CorpBase Graphics Object Load Template
H17: Synonyms | I17: =HYPERLINK(VLOOKUP(H17,'Learn More & Support'!$B:$D,2,0),"learn more") -> learn more | J17: These are additional names the product may be known as; These are simply names loaded without marking as primary. | K17: Batchloader / CorpBase Client | L17: Should not be marked "primary"; | S17: Chemical name synonyms | T17: Melting point | U17: Refractive index | W17: 3 | X17: FLUKA | Y17: F | Z17: Fluka | AA17: Not available in BatchLoader | BH17: Citations Form
D18: HOW do I use the job aid? | E18: STEP 1: Filter by 'data_definition_product_group' to identify top level product categorization | L18: should be unique from product's primary name | S18: Colour Index Number | T18: Molecular weight (daltons) | U18: Vapor Pressure | W18: 4 | X18: RIEDEL | Y18: R | Z18: Riedel-de-Haen | AA18: Not available in BatchLoader | BH18: Package Literals Template
E19: STEP 2: Filter by 'data_definition_product_type' to identify next level of product categorization | S19: Density | T19: Molecular weight | W19: 5 | X19: SUPELCO | Y19: U | Z19: Supelco | AB19: U2 | AC19: U2 | AD19: SU
E20: STEP 3: View required attributes (Attribute web_label) and priority assignment | G20: Properties | H20: Attributes | I20: =HYPERLINK(VLOOKUP(H20,'Learn More & Support'!$B:$D,2,0),"learn more") -> learn more | J20: Fixed Text Picklist | K20: Data Definition Job Aid in Confluence | L20: Reference data definition job aid for required fields | W20: 6 | X20: DIAG | Y20: D | Z20: Sigma | AA20: Not available in BatchLoader
E21: Priorities: | S21: PIM label data preview: | W21: 16 | X21: GENOSYS | Y21: G | Z21: Sigma | AA21: Not available in BatchLoader
E22: P1 = Required | G22: Trademarks | H22: Trademarks | I22: =HYPERLINK(VLOOKUP(H22,'Learn More & Support'!$B:$D,2,0),"learn more") -> learn more | J22: If applicable; Check Trademark table to verify if a trademark exists or to add new trademarks | K22: Batchloader / CorpBase Client (or Ticket) | L22: Value must exist in Trademark table | W22: 17 | X22: MM | Y22: M | Z22: Millipore | AB22: M5 | AC22: M5 | AD22: MI
E23: P2 = Critical | L23: If value exists: Batchloader / CorpBase Client | W23: 18 | X23: IVD | Y23: I | Z23: Sigma | AA23: Not available in BatchLoader
E24: P3 = Preferred | L24: If new value must be created: Enter a ticket. | W24: 19 | X24: TRINITY | Y24: Y | Z24: Sigma | AA24: Not available in BatchLoader
E25: STEP 4: Enter the provided product data into Batchloader/CorpBase PIM during NPI using the instructions provided | L25: Typical cycle time for adding/updating trademark table is ~4 weeks; | W25: 40 | X25: CERILLIAN | Y25: C | Z25: Cerilliant | AB25: C2 | AC25: C2 | AD25: CE
L26: don't just enter trademark symbols ® or ™
D27: UPDATE TO THE DATA DEF JOB AID / PDP CHECKLIST
D28: The data def job aid and PDP Checklists have now been combined into one file (this file). | G28: Aliases | H28: UNSPSC Code | I28: =HYPERLINK(VLOOKUP(H28,'Learn More & Support'!$B:$D,2,0),"learn more") -> learn more | J28: United Nations Standard Products and Services Code (UNSPSC); | K28: Batchloader / CorpBase Client | L28: CorpBase batchloader "Aliases" tab, drop down type: UNSPSC code
D29: Future updates to the the Data Definition job aid tab will automatically update the attributes/properties dynamic table on the PDP Checklist | L29: can be on substance level or product level
D30: This will ensure all PMs are using up to date product data recommendations during NPI and data def review
D31: Please be sure to always use the latest version of this file | G31: Imagery | H31: Product image | I31: =HYPERLINK(VLOOKUP(H31,'Learn More & Support'!$B:$D,2,0),"learn more") -> learn more | J31: CorpBase Graphics Object Load Template; 400 DPI or above | K31: CorpBase Graphics Request
H32: Image caption | I32: =HYPERLINK(VLOOKUP(H32,'Learn More & Support'!$B:$D,2,0),"learn more") -> learn more | J32: Load in same CorpBase Graphics Object Load Template file, using PM provided filenames and caption text | K32: CorpBase Graphics Request
H33: Chemical structure | I33: =HYPERLINK(VLOOKUP(H33,'Learn More & Support'!$B:$D,2,0),"learn more") -> learn more | J33: If applicable. Provide structure (ChemDraw) to structures@merckgroup.com | K33: structures@merckgroup.com | N33: Method 3: CorpBase | O33: enter the product number and brand you want to use on the names tab and hit validate.
N34: batchloader | O34: In this case, if anything comes back green, then that product number/brand already exists.
G35: Packaging | H35: Pack size (displayed in P&A) | I35: =HYPERLINK(VLOOKUP(H35,'Learn More & Support'!$B:$D,2,0),"learn more") -> learn more | J35: use Package Literals Template | K35: CorpBase Help Desk Request | L35: Ticket has to be submitted after Products are marked Ready in CorpBase. | N35: (Validation) | O35: Green=bad, product no/brand combination not in corpbase/RED=good
O36: (Also beware the red though if it says user doesn't have permissions to update product)
G37: Descriptions | H37: Enter the following prioritized description types at a minimum; additional descriptions can be entered | O37: So use the filter in the validation field - any blanks
H38: General Description | I38: =HYPERLINK(VLOOKUP(G37,'Learn More & Support'!$B:$D,2,0),"learn more") -> learn more | J38: Description type = General Description Long | K38: Batchloader / CorpBase Client | O38: or "user does not have permissions to edit product" those are ones that already exist)
H39: Application | J39: Description type = Application Long | K39: Batchloader / CorpBase Client
H40: Features & Benefits | J40: Description type = Features & Benefits Long | K40: Batchloader / CorpBase Client
...

Sheet Data Definition Job Aid
A1: STEP 1: filter by Column A and B; STEP 2: Reference Column E for required dataData Definition Alignment Date: 10-4-2024
A2: data_definition_product_group | B2: data_definition_product_type | C2: Attribute_web_label | D2: Priority | E2: Priority_new | F2: CB_batchloader_-_which_tab | G2: Please_use_drop_downs_and_select | H2: Notes | I2: Example_Product_Number | J2: Example_Data | K2: Facet_YN | L2: Facet_Label | M2: facet_requirements | N2: facet_string
A3: acids and bases | C3: CAS_NO | D3: Basic Data | E3: Priority 1 | F3: CAS | G3: Select TYPE, enter the CAS NUMBER, select PUBLISHING FLAG | H3: must be on the substance level | I3: 1.0183 | J3: 64-19-7 | K3: N
A4: acids and bases | C4: NAME_ENGLISH_1 | D4: Basic Data | E4: Priority 1 | F4: Names | G4: Choose NAME TYPE; PRM EN; ROOT NAME EN | H4: enter other keywords, names…etc. on this tab | I4: 1.00686 | J4: Sulfanilic acid | K4: N
A5: acids and bases | C5: NAME_SUFFIX_ENGLISH_1 | D5: Basic Data | E5: Priority 1 | F5: ProductAttributes | G5: Select product attributes using NAME SUFFIX SEQUENCE (1,2,3,4…etc) | I5: 1.00686 | J5: GR for analysis ACS,Reag. Ph Eur | K5: N
A6: acids and bases | C6: UNSPSC_CODE | D6: Basic Data | E6: Priority 1 | F6: Aliases | G6: drop down type: UNSPSC code | H6: can be on substance level or product level | I6: 1.00686 | J6: 12352106 | K6: N
A7: acids and bases | C7: concentration | D7: Facet driving attribute | E7: Priority 1 | F7: ProductAttributes | G7: ATTRIBUTE TYPE: Concentration | I7: 1.00713 | J7: 95-98% | K7: N
A8: acids and bases | C8: form | D8: Facet driving attribute | E8: Priority 1 | F8: ProductAttributes | G8: ATTRIBUTE TYPE: Physical Form | I8: 1.00682 | J8: solid | K8: Y | L8: Physical Form | M8: ?
A9: acids and bases | C9: grade | D9: Facet driving attribute | E9: Priority 1 | F9: ProductAttributes | G9: ATTRIBUTE TYPE: Special Grade and web special grade | H9: web special grade is facetable; but web special grade does not show on the PDP; special grade is the opposite | I9: 1.00686 | J9: ACS reagent | K9: Y | L9: Grade | M9: web special grade
A10: acids and bases | C10: assay | D10: High priority attribute | E10: Priority 2 | F10: ProductAttributes | G10: ATTRIBUTE TYPE: Assay | I10: 1.00686 | J10: ≥99.0-102.0% (acidimetric) | K10: Y | L10: Purity | M10: ?
A11: acids and bases | C11: InChI | D11: High priority attribute | E11: Priority 2 | F11: Aliases | G11: drop down type: InChl | H11: must be on the substance level | I11: 1.00686 | J11: 1S/C6H7NO3S/c7-5-1-3-6(4-2-5)11(8,9)10/h1-4H,7H2,(H,8,9,10) | K11: N
A12: acids and bases | C12: InChI key | D12: High priority attribute | E12: Priority 2 | F12: Aliases | G12: drop down type: InChl key | H12: must be on the substance level | I12: 1.00686 | J12: HVBSAKJJOYLTQU-UHFFFAOYSA-N | K12: N
A13: acids and bases | C13: pH | D13: High priority attribute | E13: Priority 2 | F13: ProductAttributes | G13: ATTRIBUTE TYPE: pH value | I13: 1.00686 | J13: 2.5 (20 °C, 10 g/L in H2O) | K13: Y | L13: pH | M13: ?
A14: acids and bases | C14: SMILES string | D14: High priority attribute | E14: Priority 2 | F14: Aliases | G14: drop down type: SMILES | H14: must be on the substance level; 30 characters or less; if more than 30 characters, raise a JIRA for CorpBase Helpdesk | I14: 1.00682 | J14: OC(=O)CCC(O)=O | K14: N
A15: acids and bases | C15: solubility | D15: High priority attribute | E15: Priority 2 | F15: ProductAttributes | G15: ATTRIBUTE TYPE: Solubility | I15: 1.00686 | J15: water: 10 g/L at 20 °C | K15: N
A16: acids and bases | C16: storage temp. | D16: High priority attribute | E16: Priority 2 | F16: ProductAttributes | G16: ATTRIBUTE TYPE: Storage Temp | I16: 1.00686 | J16: 15-25°C | K16: N
A17: acids and bases | C17: agency | D17: Low priority attribute | E17: Priority 3 | F17: ProductAttributes | G17: ATTRIBUTE TYPE: Agency/Method | H17: create separate lines for different values | I17: 1.00686 | J17: reag. Ph. Eur. | K17: Y | L17: Agency | N17: agency element
A18: acids and bases | C18: anion traces | D18: Low priority attribute | E18: Priority 3 | F18: ProductAttributes | G18: ATTRIBUTE TYPE: Anion Traces | I18: 1.00686 | J18: chloride (Cl-): ≤0.002%; nitrite (NO2-): ≤0.5 ppm; sulfate (SO42-): ≤0.01% | K18: N
A19: acids and bases | C19: bp | D19: Low priority attribute | E19: Priority 3 | F19: ProductAttributes | G19: ATTRIBUTE TYPE: Boiling Point | I19: 1.00682 | J19: 235 °C (lit.); 235 °C/1013 hPa | K19: Y | L19: boiling point | M19: ?
A20: acids and bases | C20: cation traces | D20: Low priority attribute | E20: Priority 3 | F20: ProductAttributes | G20: ATTRIBUTE TYPE: Cation Traces | I20: 1.00686 | J20: heavy metals (as Pb): ≤0.001% | K20: N
A21: acids and bases | C21: density | D21: Low priority attribute | E21: Priority 3 | F21: ProductAttributes | G21: ATTRIBUTE TYPE: Density | I21: 1.00686 | J21: 620 kg/m3 | K21: N
A22: acids and bases | C22: impurities | D22: Low priority attribute | E22: Priority 3 | F22: ProductAttributes | G22: ATTRIBUTE TYPE: Impurities | I22: 1.00452 | J22: ≤0.005 ppm Hg (Mercury) | K22: N
A23: acids and bases | C23: mp | D23: Low priority attribute | E23: Priority 3 | F23: ProductAttributes | G23: ATTRIBUTE TYPE: Melting Point | I23: 1.00686 | J23: 288 °C (decomposes) | K23: Y | L23: mp | M23: ?
A24: acids and bases | C24: refractive index | D24: Low priority attribute | E24: Priority 3 | F24: ProductAttributes | G24: ATTRIBUTE TYPE: Refractive Index | I24: 1.0183 | J24: n20/D 1.371 (lit.) | K24: N
A25: acids and bases | C25: vapor density | D25: Low priority attribute | E25: Priority 3 | F25: ProductAttributes | G25: ATTRIBUTE TYPE: Vapor density vs air | I25: 1.00714 | J25: <0.3 (25 °C, vs air) | K25: N
A26: acids and bases | C26: vapor pressure | D26: Low priority attribute | E26: Priority 3 | F26: ProductAttributes | G26: ATTRIBUTE TYPE: Vapor pressure | I26: 1.00452 | J26: 9.4 hPa ( 20 °C) | K26: N
A27: adapters | B27: pressure fittings | C27: NAME_ENGLISH_1 | D27: Basic Data | E27: Priority 1 | F27: Names | G27: Choose NAME TYPE; PRM EN; ROOT NAME EN | H27: enter other keywords, names…etc. on this tab | I27: PYR0CNT01 | J27: Pyrogard® D Point-of-Use Connector | K27: N
A28: adapters | B28: pressure fittings | C28: NAME_SUFFIX_ENGLISH_1 | D28: Basic Data | E28: Priority 1 | F28: ProductAttributes | G28: Select product attributes using NAME SUFFIX SEQUENCE (1,2,3,4…etc) | I28: PYR0CNT01 | J28: For use with Pyrogard® D ultrafiltration cartridge | K28: N
A29: adapters | B29: pressure fittings | C29: UNSPSC_CODE | D29: Basic Data | E29: Priority 1 | F29: Aliases | G29: drop down type: UNSPSC code | H29: can be on substance level or product level | I29: PYR0CNT01 | J29: 41104214 | K29: N
A30: adapters | B30: pressure fittings | C30: compatibility | D30: Facet driving attribute | E30: Priority 1 | F30: ProductAttributes | G30: ATTRIBUTE TYPE: ZM_COMPAT | H30: create separate lines for different values -- facet must use 1 or both of supplier and product line | I30: PYR0CNT01 | J30: for use with Milli-Q® Academic | K30: Y | L30: compatibility | M30: res=for use with, product line or manufacturer not empty | N30: Manufact Product line used with
A31: adapters | B31: pressure fittings | C31: fitting | D31: High priority attribute | E31: Priority 2 | F31: ProductAttributes | G31: ATTRIBUTE TYPE: fittings threads | I31: PYR0CNT01 | J31: 1/4 in. inlet connection; 1/4 in. outlet connection | K31: M | M31: part=thread | N31: fitsSize
A32: adapters | B32: pressure fittings | C32: packaging | D32: Low priority attribute | E32: Priority 3 | F32: ProductAttributes | G32: ATTRIBUTE TYPE: Packaging quantity | H32: facet only on pack_id (was NEVER used on the red site - utility is dubious) | I32: PYR0CNT01 | J32: pkg of 1 unit | K32: Y | L32: packaging | M32: pack_id | N32: pack_id
A33: adapters | B33: pressure fittings | C33: pore size | D33: Low priority attribute | E33: Priority 3 | F33: ProductAttributes | G33: ATTRIBUTE TYPE: Pore size | I33: PYR0CNT01 | J33: 0.45 μm pore size (CRW5 type) | K33: Y | L33: Pore size | M33: uom in um, or A, or kDa
A34: adapters | B34: pressure fittings | C34: shipped in | D34: Low priority attribute | E34: Priority 3 | F34: ProductAttributes | G34: ATTRIBUTE TYPE: Ice Shipping | I34: PYR0CNT01 | J34: dry ice, wet ice, ambient | K34: N
A35: adapters | C35: NAME_ENGLISH_1 | D35: Basic Data | E35: Priority 1 | F35: Names | G35: Choose NAME TYPE; PRM EN; ROOT NAME EN | H35: enter other keywords, names…etc. on this tab | I35: Z252301 | J35: Aldrich® anticlimb splash-guard adapter with fritted disc | K35: N
A36: adapters | C36: NAME_SUFFIX_ENGLISH_1 | D36: Basic Data | E36: Priority 1 | F36: ProductAttributes | G36: Select product attributes using NAME SUFFIX SEQUENCE (1,2,3,4…etc) | I36: Z252301 | J36: female Joint: ST/NS 24/40, male Joint: ST/NS 24/40, capacity 500 mL | K36: N
A37: adapters | C37: UNSPSC_CODE | D37: Basic Data | E37: Priority 1 | F37: Aliases | G37: drop down type: UNSPSC code | H37: can be on substance level or product level | I37: Z252301 | J37: 41121815 | K37: N
A38: adapters | C38: feature | D38: Facet driving attribute | E38: Priority 1 | F38: ProductAttributes | G38: ATTRIBUTE TYPE: Feature | H38: use the drop down to select a "Name" (for tubing i.d./for tubing o.d.) | I38: GE18114710 | J38: Wetted Material: Polyetheretherketone (PEEK); Connections: Fingertight 1/16"; ÄKTA® Systems | K38: N
A39: adapters | C39: fitting | D39: Facet driving attribute | E39: Priority 1 | F39: ProductAttributes | G39: ATTRIBUTE TYPE: fittings threads | I39: XX42T19H6 | J39: 1/4 in. hose barb; 3/4 in. sanitary clamp | K39: M | M39: part=thread | N39: fitsSize
A40: adapters | C40: joint | D40: Facet driving attribute | E40: Priority 1 | F40: ProductAttributes | G40: ATTRIBUTE TYPE: Standard Joint, choose part
...

Sheet LOGIC
A1: Dynamic Cat1 | B1: Dynamic Cat2 | D1: UNIQUE GROUP | E1: UNIQUE TYPE | H1: PULLED FROM DD JOB AID --> | I1: data_definition_product_group | J1: data_definition_product_type | K1: Attribute_web_label | L1: Priority | M1: Priority_new | N1: CB_batchloader_-_which_tab | O1: Please_use_drop_downs_and_select | P1: Notes | Q1: Example_Product_Number | R1: Example_Data | S1: Facet_YN | T1: Facet_Label | U1: facet_requirements | V1: facet_string
A2: {=_xlfn.UNIQUE(_xlfn._xlws.FILTER(D2:D1000000,(D2:D1000000<>"(no product type)") * (D2:D1000000<>"")))} -> 1. Select Product Group | B2: {=IFERROR(_xlfn._xlws.FILTER(E2:E1000000,D2:D1000000='PDP Checklist'!$I$7),"Select Product Type")} -> various | D2: {=IF(_xlfn.UNIQUE(I2:J1000000)=0, "(no product type)", _xlfn.UNIQUE(I2:J1000000))} -> 1. Select Product Group | E2: 2. Select Product Type | H2: filtered "Basic Data" out unique (some dups in DD) | I2: 1. Select Product Group | J2: 2. Select Product Type
A3: acids and bases | D3: acids and bases | E3: (no product type) | G3: Combine Dynamic group and type columns --> | H3: {=INDEX(_xlfn.ANCHORARRAY(I3), 0, 1)&IF(INDEX(_xlfn.ANCHORARRAY(I3), 0, 2)=0,"(no product type)",INDEX(_xlfn.ANCHORARRAY(I3), 0, 2))} -> acids and bases(no product type) | I3: {=_xlfn.UNIQUE(_xlfn._xlws.FILTER('Data Definition Job Aid'!A3:N999552,('Data Definition Job Aid'!D3:D999552<>"Basic Data") * ('Data Definition Job Aid'!D3:D999552<>"")))} -> acids and bases | J3: 0 | K3: concentration | L3: Facet driving attribute | M3: Priority 1 | N3: ProductAttributes | O3: ATTRIBUTE TYPE: Concentration | P3: 0 | Q3: 1.00713 | R3: 95-98% | S3: N | T3: 0 | U3: 0 | V3: 0
